#VRML_SIM R2021a utf8
WorldInfo {
  basicTimeStep 16
  coordinateSystem "NUE"
  contactProperties [
    ContactProperties {
      material2 "db"
    }
  ]
}
Viewpoint {
  orientation -0.9408678556831912 0.006471493657048582 0.3387119689529152 0.6947152146693477
  position 0.024469485598562338 0.2084032009643023 0.18031423327746346
}
TexturedBackground {
  texture "empty_office"
}
Solid {
  translation -0.008079703952792273 0.049801032994070446 -0.48999010472678795
  rotation 0.9999516307451175 0.006849060562510766 -0.00705879165234742 0.0002685828210897808
  children [
    DEF wall Shape {
      appearance PBRAppearance {
        metalness 0
      }
      geometry Box {
        size 1 0.1 0.02
      }
    }
    Solid {
    }
  ]
  boundingObject USE wall
  physics Physics {
    mass 1
  }
}
Solid {
  translation 0.49587736562785895 0.04941201204764952 -0.00010082384214265053
  rotation 0.002780531689691169 0.9999923691958785 -0.002744119810899838 1.558806025652835
  children [
    USE wall
  ]
  name "solid(3)"
  boundingObject USE wall
  physics Physics {
    density -1
    mass 3
  }
}
Solid {
  translation -0.5043192435974416 0.04980359778803644 -0.00018927736217490726
  rotation -0.001783287423396763 0.9999967213039295 0.0018377342997929588 1.5990719667998163
  children [
    USE wall
  ]
  name "solid(4)"
  boundingObject USE wall
  physics Physics {
    mass 1
  }
}
TexturedBackgroundLight {
  texture "noon_cloudy_countryside"
}
Floor {
  size 1 1
}
Solid {
  translation 1.8538176409516248e-06 0.049804788394875926 0.5098097707682363
  rotation -0.9985829694539226 0.05321689778010531 0.00012209524239826304 -0.003326863508953586
  children [
    USE wall
  ]
  name "solid(2)"
  boundingObject USE wall
  physics Physics {
    mass 1
  }
  locked TRUE
}
Robot {
  translation 1.5772773983484343e-07 0.014987852077356761 -2.7077598783004215e-10
  rotation -0.0017299110720844107 1.5152401891386346e-07 -0.9999985037027104 1.0450934496293419e-05
  children [
    LED {
      translation 0 0.06 0
      children [
        Shape {
          appearance PBRAppearance {
          }
          geometry Cylinder {
            bottom FALSE
            height 0.1
            radius 0.005
          }
        }
      ]
      name "led1"
      gradual TRUE
    }
    DEF body Shape {
      appearance PBRAppearance {
        baseColor 1 1 0
        roughness 1
        metalness 0
      }
      geometry Box {
        size 0.1 0.02 0.05
      }
    }
    HingeJoint {
      jointParameters HingeJointParameters {
        position -5.433326798852158e-12
        axis 0 0 1
        anchor 0.03 0 0.03
      }
      device [
        RotationalMotor {
          name "RF"
        }
      ]
      endPoint Solid {
        translation 0.03 0 0.03
        rotation 1 -9.779988237933899e-11 -9.779952314097166e-11 1.5708
        children [
          DEF wheel Shape {
            appearance PBRAppearance {
              baseColor 1 0 0
              roughness 1
            }
            geometry Cylinder {
              height 0.007
              radius 0.015
            }
          }
        ]
        boundingObject USE wheel
        physics DEF wheel_physics Physics {
        }
      }
    }
    HingeJoint {
      jointParameters HingeJointParameters {
        position -5.43198654185848e-12
        axis 0 0 1
        anchor 0.03 0 -0.03
      }
      device [
        RotationalMotor {
          name "LF"
        }
      ]
      endPoint Solid {
        translation 0.03 0 -0.03
        rotation 1 -9.777575775345277e-11 -9.777539860370001e-11 1.5708
        children [
          USE wheel
        ]
        name "solid(1)"
        boundingObject USE wheel
        physics USE wheel_physics
      }
    }
    HingeJoint {
      jointParameters HingeJointParameters {
        position 5.428544321950634e-12
        axis 0 0 1
        anchor -0.03 0 -0.03
      }
      device [
        RotationalMotor {
          name "LB"
        }
      ]
      endPoint Solid {
        translation -0.03 0 -0.03
        rotation 1 9.771379779511156e-11 9.771343887295003e-11 1.5708
        children [
          USE wheel
        ]
        name "solid(2)"
        boundingObject USE wheel
        physics USE wheel_physics
      }
    }
    HingeJoint {
      jointParameters HingeJointParameters {
        position 5.431138058583978e-12
        axis 0 0 1
        anchor -0.03 0 0.03
      }
      device [
        RotationalMotor {
          name "RB"
        }
      ]
      endPoint Solid {
        translation -0.03 0 0.03
        rotation 3.4596158571961305e-09 -0.7071047811843381 0.7071087811831003 3.1415900001382573
        children [
          USE wheel
        ]
        name "solid(3)"
        boundingObject USE wheel
        physics USE wheel_physics
      }
    }
    DistanceSensor {
      translation 0.047 0 -0.00999999
      rotation 0 1 0 0.3
      children [
        DEF DS Shape {
          appearance PBRAppearance {
            baseColor 0 0 0
          }
          geometry Box {
            size 0.01 0.01 0.01
          }
        }
      ]
      name "DSL"
      boundingObject USE DS
      physics Physics {
      }
    }
    DistanceSensor {
      translation 0.047 0 0.01
      rotation 0 1 0 -0.3
      children [
        USE DS
      ]
      name "DSR"
      boundingObject USE DS
      physics Physics {
      }
    }
  ]
  boundingObject USE body
  physics Physics {
    mass 0.1
  }
  controller "my_controllerled"
}
