#VRML_SIM R2021a utf8
WorldInfo {
  basicTimeStep 16
  coordinateSystem "NUE"
  contactProperties [
    ContactProperties {
      material2 "db"
    }
  ]
}
Viewpoint {
  orientation -0.5448847964201994 -0.8383197211377365 -0.017905412077518515 1.0537371672883045
  position -0.8636248956242325 0.6345734060584763 0.6136515435787504
}
TexturedBackground {
  texture "empty_office"
}
Solid {
  translation -0.008062198130529224 0.049800968157670746 -0.4899867298279295
  rotation 0.9999797479317348 0.003784106944197555 -0.005117055893648925 0.0003104307107748363
  children [
    DEF wall Shape {
      appearance PBRAppearance {
        metalness 0
      }
      geometry Box {
        size 1 0.1 0.02
      }
    }
    Solid {
    }
  ]
  boundingObject USE wall
  physics Physics {
    mass 1
  }
}
Solid {
  translation 0.49588430429556046 0.04941191222576135 -9.175912807898598e-05
  rotation 0.003152829590225926 0.9999901848398858 -0.0031128587289397745 1.5588665050844672
  children [
    USE wall
  ]
  name "solid(3)"
  boundingObject USE wall
  physics Physics {
    density -1
    mass 3
  }
}
Solid {
  translation -0.5043096355867439 0.04980365813702876 -0.00017878554569551174
  rotation -0.0018129763496646657 0.9999966109071255 0.0018684996704759042 1.599048544850297
  children [
    USE wall
  ]
  name "solid(4)"
  boundingObject USE wall
  physics Physics {
    mass 1
  }
}
TexturedBackgroundLight {
  texture "noon_cloudy_countryside"
}
Floor {
  size 1 1
}
Solid {
  translation 1.5747760859526481e-06 0.04980452569188582 0.509826964815639
  rotation -0.9990242896487171 0.04416386249224931 0.0001481271133544755 -0.004077099932754941
  children [
    USE wall
  ]
  name "solid(2)"
  boundingObject USE wall
  physics Physics {
    mass 1
  }
  locked TRUE
}
Robot {
  translation 0 0.05 0
  children [
    DEF body Shape {
      appearance PBRAppearance {
        baseColor 1 1 0
        roughness 1
        metalness 0
      }
      geometry Box {
        size 0.1 0.02 0.05
      }
    }
    HingeJoint {
      jointParameters HingeJointParameters {
        axis 0 0 1
        anchor 0.03 0 0.03
      }
      device [
        RotationalMotor {
          name "RF"
        }
      ]
      endPoint Solid {
        translation 0.03 0 0.03
        rotation 1 0 0 1.5708
        children [
          DEF wheel Shape {
            appearance PBRAppearance {
              baseColor 1 0 0
              roughness 1
            }
            geometry Cylinder {
              height 0.007
              radius 0.015
            }
          }
        ]
        boundingObject USE wheel
        physics DEF wheel_physics Physics {
        }
      }
    }
    HingeJoint {
      jointParameters HingeJointParameters {
        axis 0 0 1
        anchor 0.03 0 -0.03
      }
      device [
        RotationalMotor {
          name "LF"
        }
      ]
      endPoint Solid {
        translation 0.03 0 -0.03
        rotation 1 0 0 1.5708
        children [
          USE wheel
        ]
        name "solid(1)"
        boundingObject USE wheel
        physics USE wheel_physics
      }
    }
    HingeJoint {
      jointParameters HingeJointParameters {
        axis 0 0 1
        anchor -0.03 0 -0.03
      }
      device [
        RotationalMotor {
          name "LB"
        }
      ]
      endPoint Solid {
        translation -0.03 0 -0.03
        rotation 1 0 0 1.5708
        children [
          USE wheel
        ]
        name "solid(2)"
        boundingObject USE wheel
        physics USE wheel_physics
      }
    }
    HingeJoint {
      jointParameters HingeJointParameters {
        axis 0 0 1
        anchor -0.03 0 0.03
      }
      device [
        RotationalMotor {
          name "RB"
        }
      ]
      endPoint Solid {
        translation -0.03 0 0.03
        rotation 3.3904889508031858e-09 -0.7071047811843381 0.7071087811831003 3.14159
        children [
          USE wheel
        ]
        name "solid(3)"
        boundingObject USE wheel
        physics USE wheel_physics
      }
    }
    DistanceSensor {
      translation 0.047 0 -0.00999999
      rotation 0 1 0 0.3
      children [
        DEF DS Shape {
          appearance PBRAppearance {
            baseColor 0 0 0
          }
          geometry Box {
            size 0.01 0.01 0.01
          }
        }
      ]
      name "DSL"
      boundingObject USE DS
      physics Physics {
      }
    }
    DistanceSensor {
      translation 0.047 0 0.01
      rotation 0 1 0 -0.3
      children [
        USE DS
      ]
      name "DSR"
      boundingObject USE DS
      physics Physics {
      }
    }
  ]
  boundingObject USE body
  physics Physics {
    mass 0.1
  }
  controller "my_controller3"
}
