#VRML_SIM R2021a utf8
WorldInfo {
  basicTimeStep 16
  coordinateSystem "NUE"
  contactProperties [
    ContactProperties {
      material2 "db"
    }
  ]
}
Viewpoint {
  orientation 0.10289612286723085 0.9779594324418686 0.18168031372955623 3.0617810603899347
  position 1.0529894973928728 2.000066038121414 -4.131735234032301
}
TexturedBackground {
  texture "empty_office"
}
Solid {
  translation -0.008092953259389916 0.049801114848935575 -0.4899927367467895
  rotation 0.9999153982198894 0.009771532660857129 -0.00858565968448822 0.0002390122680913917
  children [
    DEF wall Shape {
      appearance PBRAppearance {
        metalness 0
      }
      geometry Box {
        size 1 0.1 0.02
      }
    }
    Solid {
    }
  ]
  boundingObject USE wall
  physics Physics {
    mass 1
  }
}
Solid {
  translation 0.49587221551326727 0.0494121265929737 -0.00010793080845462339
  rotation 0.0024742650305298835 0.9999939613547565 -0.002440341488513328 1.5587554092698188
  children [
    USE wall
  ]
  name "solid(3)"
  boundingObject USE wall
  physics Physics {
    density -1
    mass 3
  }
}
Solid {
  translation -0.5043268242992475 0.04980360666736011 -0.00019897952963490178
  rotation -0.0017390379567153306 0.9999968837458437 0.0017911576107338958 1.5990944607096493
  children [
    USE wall
  ]
  name "solid(4)"
  boundingObject USE wall
  physics Physics {
    mass 1
  }
}
TexturedBackgroundLight {
  texture "noon_cloudy_countryside"
}
Floor {
  size 1 1
}
Robot {
  translation 0.0400002 0.0149875 0.05
  rotation -0.0017299110491267918 1.6516425290031624e-07 -0.999998503702748 1.0450934496361327e-05
  children [
    LED {
      translation 0 0.015 0
      children [
        Shape {
          appearance PBRAppearance {
            roughness 1
          }
          geometry Cylinder {
            bottom FALSE
            height 0.01
            radius 0.005
          }
        }
      ]
      name "led1"
      gradual TRUE
    }
    DEF body Shape {
      appearance PBRAppearance {
        baseColor 1 1 0
        roughness 1
        metalness 0
      }
      geometry Box {
        size 0.1 0.02 0.05
      }
    }
    Group {
      children [
        Transform {
        }
        USE body
      ]
    }
    HingeJoint {
      jointParameters HingeJointParameters {
        position -6.319728861712883e-12
        axis 0 0 1
        anchor 0.03 0 0.03
      }
      device [
        RotationalMotor {
          name "RF"
        }
      ]
      endPoint Solid {
        translation 0.03 0 0.03
        rotation 1 -5.539621201221373e-11 -5.539600853093867e-11 1.5708
        children [
          DEF wheel Shape {
            appearance PBRAppearance {
              baseColor 1 0 0
              roughness 1
            }
            geometry Cylinder {
              height 0.007
              radius 0.015
            }
          }
        ]
        boundingObject USE wheel
        physics DEF wheel_physics Physics {
        }
      }
    }
    HingeJoint {
      jointParameters HingeJointParameters {
        position -6.31710485621846e-12
        axis 0 0 1
        anchor 0.03 0 -0.03
      }
      device [
        RotationalMotor {
          name "LF"
        }
      ]
      endPoint Solid {
        translation 0.03 0 -0.03
        rotation 1 -5.6161742799581674e-11 -5.6161536506360284e-11 1.5708
        children [
          USE wheel
        ]
        name "solid(1)"
        boundingObject USE wheel
        physics USE wheel_physics
      }
    }
    HingeJoint {
      jointParameters HingeJointParameters {
        position 4.541254080670209e-12
        axis 0 0 1
        anchor -0.03 0 -0.03
      }
      device [
        RotationalMotor {
          name "LB"
        }
      ]
      endPoint Solid {
        translation -0.03 0 -0.03
        rotation 1 7.249632133179984e-12 7.249605503843347e-12 1.5708
        children [
          USE wheel
        ]
        name "solid(2)"
        boundingObject USE wheel
        physics USE wheel_physics
      }
    }
    HingeJoint {
      jointParameters HingeJointParameters {
        position 4.05626082537562e-12
        axis 0 0 1
        anchor -0.03 0 0.03
      }
      device [
        RotationalMotor {
          name "RB"
        }
      ]
      endPoint Solid {
        translation -0.03 0 0.03
        rotation 3.3862523527919665e-09 -0.7071047811843382 0.7071087811831 3.1415899999915395
        children [
          USE wheel
        ]
        name "solid(3)"
        boundingObject USE wheel
        physics USE wheel_physics
      }
    }
  ]
  boundingObject USE body
  physics Physics {
    mass 0.1
  }
  controller "my_controller_car"
}
DEF sdfsdg Robot {
  scale 0.1 0.1 0.1
  children [
    DEF dhdfhdfhd Solid {
      children [
        Shape {
          appearance PBRAppearance {
            roughness 1
            metalness 0
            name "DefaultMaterial"
          }
          geometry IndexedFaceSet {
            coord Coordinate {
              point [
                10.1368 2 2.5641, 10.1368 2 12.5641, 10.1368 0 2.5641, 10.1368 0 12.5641, 12.0684 2 2.5641, 10.1368 2 2.5641, 12.0684 0 2.5641, 10.1368 0 2.5641, 12.0684 2 0, 12.0684 2 2.5641, 12.0684 0 0, 12.0684 0 2.5641, 0 2 0, 12.0684 2 0, 0 0 0, 12.0684 0 0, 0 2 2.5641, 0 2 0, 0 0 2.5641, 0 0 0, 1.93162 2 2.5641, 0 2 2.5641, 1.93162 0 2.5641, 0 0 2.5641, 1.93162 2 12.5641, 1.93162 2 2.5641, 1.93162 0 12.5641, 1.93162 0 2.5641, 10.1368 2 12.5641, 1.93162 2 12.5641, 10.1368 0 12.5641, 1.93162 0 12.5641, 10.1368 2 2.5641, 12.0684 2 2.5641, 12.0684 2 0, 0 2 0, 0 2 2.5641, 1.93162 2 2.5641, 1.93162 2 12.5641, 10.1368 2 12.5641, 1.93162 0 2.5641, 0 0 2.5641, 0 0 0, 12.0684 0 0, 12.0684 0 2.5641, 10.1368 0 2.5641, 10.1368 0 12.5641, 1.93162 0 12.5641
              ]
            }
            normal Normal {
              vector [
                1 0 0, 1 0 0, 1 0 0, 1 0 0, 0 0 1, 0 0 1, 0 0 1, 0 0 1, 1 0 0, 1 0 0, 1 0 0, 1 0 0, 0 0 -1, 0 0 -1, 0 0 -1, 0 0 -1, -1 0 0, -1 0 0, -1 0 0, -1 0 0, 0 0 1, 0 0 1, 0 0 1, 0 0 1, -1 0 0, -1 0 0, -1 0 0, -1 0 0, 0 0 1, 0 0 1, 0 0 1, 0 0 1, 0 1 0, 0 1 0, 0 1 0, 0 1 0, 0 1 0, 0 1 0, 0 1 0, 0 1 0, 0 -1 0, 0 -1 0, 0 -1 0, 0 -1 0, 0 -1 0, 0 -1 0, 0 -1 0, 0 -1 0
              ]
            }
            coordIndex [
              0, 1, 2, -1, 2, 1, 3, -1, 4, 5, 6, -1, 6, 5, 7, -1, 8, 9, 10, -1, 10, 9, 11, -1, 12, 13, 14, -1, 14, 13, 15, -1, 16, 17, 18, -1, 18, 17, 19, -1, 20, 21, 22, -1, 22, 21, 23, -1, 24, 25, 26, -1, 26, 25, 27, -1, 28, 29, 30, -1, 30, 29, 31, -1, 32, 33, 34, -1, 35, 36, 37, -1, 38, 39, 37, -1, 37, 39, 32, -1, 37, 32, 35, -1, 35, 32, 34, -1, 40, 41, 42, -1, 43, 44, 45, -1, 46, 47, 45, -1, 45, 47, 40, -1, 45, 40, 43, -1, 43, 40, 42, -1
            ]
          }
        }
      ]
      name ""
    }
  ]
  name "<STL_BINARY>"
}
