#VRML_SIM R2021a utf8
WorldInfo {
  basicTimeStep 16
  coordinateSystem "NUE"
  contactProperties [
    ContactProperties {
      material2 "db"
    }
  ]
}
Viewpoint {
  orientation 0.004799597982494107 0.9630326796704742 0.2693418306648862 2.2600348151121428
  position 0.44005431627155456 0.179148858184529 -0.1686302926899842
}
TexturedBackground {
  texture "empty_office"
}
Solid {
  translation -0.008092953259389916 0.049801114848935575 -0.4899927367467895
  rotation 0.9999153982198894 0.009771532660857129 -0.00858565968448822 0.0002390122680913917
  children [
    DEF wall Shape {
      appearance PBRAppearance {
        metalness 0
      }
      geometry Box {
        size 1 0.1 0.02
      }
    }
    Solid {
    }
  ]
  boundingObject USE wall
  physics Physics {
    mass 1
  }
}
Solid {
  translation 0.49587221551326727 0.0494121265929737 -0.00010793080845462339
  rotation 0.0024742650305298835 0.9999939613547565 -0.002440341488513328 1.5587554092698188
  children [
    USE wall
  ]
  name "solid(3)"
  boundingObject USE wall
  physics Physics {
    density -1
    mass 3
  }
}
Solid {
  translation -0.5043268242992475 0.04980360666736011 -0.00019897952963490178
  rotation -0.0017390379567153306 0.9999968837458437 0.0017911576107338958 1.5990944607096493
  children [
    USE wall
  ]
  name "solid(4)"
  boundingObject USE wall
  physics Physics {
    mass 1
  }
}
TexturedBackgroundLight {
  texture "noon_cloudy_countryside"
}
Floor {
  size 1 1
}
Robot {
  translation 0.0400002 0.0149875 0.05
  rotation -0.0017299110491267918 1.6516425290031624e-07 -0.999998503702748 1.0450934496361327e-05
  children [
    Group {
    }
    LED {
      translation 0 0.015 0
      children [
        Shape {
          appearance PBRAppearance {
            roughness 1
          }
          geometry Cylinder {
            bottom FALSE
            height 0.01
            radius 0.005
          }
        }
      ]
      name "led1"
      gradual TRUE
    }
    DEF body Shape {
      appearance PBRAppearance {
        baseColor 1 1 0
        roughness 1
        metalness 0
      }
      geometry Box {
        size 0.1 0.02 0.05
      }
    }
    HingeJoint {
      jointParameters HingeJointParameters {
        position -6.319728861712883e-12
        axis 0 0 1
        anchor 0.03 0 0.03
      }
      device [
        RotationalMotor {
          name "RF"
        }
      ]
      endPoint Solid {
        translation 0.03 0 0.03
        rotation 1 -4.2756754288787935e-11 -4.2756597234748245e-11 1.5708
        children [
          DEF wheel Shape {
            appearance PBRAppearance {
              baseColor 1 0 0
              roughness 1
            }
            geometry Cylinder {
              height 0.007
              radius 0.015
            }
          }
        ]
        boundingObject USE wheel
        physics DEF wheel_physics Physics {
        }
      }
    }
    HingeJoint {
      jointParameters HingeJointParameters {
        position -6.31710485621846e-12
        axis 0 0 1
        anchor 0.03 0 -0.03
      }
      device [
        RotationalMotor {
          name "LF"
        }
      ]
      endPoint Solid {
        translation 0.03 0 -0.03
        rotation 1 -4.352753308714474e-11 -4.3527373201881726e-11 1.5708
        children [
          USE wheel
        ]
        name "solid(1)"
        boundingObject USE wheel
        physics USE wheel_physics
      }
    }
    HingeJoint {
      jointParameters HingeJointParameters {
        position 4.541254080670209e-12
        axis 0 0 1
        anchor -0.03 0 -0.03
      }
      device [
        RotationalMotor {
          name "LB"
        }
      ]
      endPoint Solid {
        translation -0.03 0 -0.03
        rotation 1 -1.8328760281604353e-12 -1.8328692956430144e-12 1.5708
        children [
          USE wheel
        ]
        name "solid(2)"
        boundingObject USE wheel
        physics USE wheel_physics
      }
    }
    HingeJoint {
      jointParameters HingeJointParameters {
        position 4.05626082537562e-12
        axis 0 0 1
        anchor -0.03 0 0.03
      }
      device [
        RotationalMotor {
          name "RB"
        }
      ]
      endPoint Solid {
        translation -0.03 0 0.03
        rotation 3.3805159499452586e-09 -0.7071047811843382 0.7071087811831 3.141589999980066
        children [
          USE wheel
        ]
        name "solid(3)"
        boundingObject USE wheel
        physics USE wheel_physics
      }
    }
  ]
  boundingObject USE body
  physics Physics {
    mass 0.1
  }
  controller "my_controller_car"
}
