<?xml version="1.0" encoding="utf-8"?>
<!-- This URDF was automatically created by SolidWorks to URDF Exporter! Originally created by Stephen Brawner (brawner@gmail.com) 
     Commit Version: 1.6.0-1-g15f4949  Build Version: 1.6.7594.29634
     For more information, please see http://wiki.ros.org/sw_urdf_exporter -->
<robot
  name="urdf12">
  <link
    name="base_link">
    <inertial>
      <origin
        xyz="-1.3388E-17 0.022088 0.009928"
        rpy="0 0 0" />
      <mass
        value="0.73548" />
      <inertia
        ixx="0.0035158"
        ixy="1.0473E-18"
        ixz="1.8275E-21"
        iyy="0.0018588"
        iyz="5.1248E-06"
        izz="0.0053257" />
    </inertial>
    <visual>
      <origin
        xyz="0 0 0"
        rpy="0 0 0" />
      <geometry>
        <mesh
          filename="package://urdf12/meshes/base_link.STL" />
      </geometry>
      <material
        name="">
        <color
          rgba="0.79216 0.81961 0.93333 1" />
      </material>
    </visual>
    <collision>
      <origin
        xyz="0 0 0"
        rpy="0 0 0" />
      <geometry>
        <mesh
          filename="package://urdf12/meshes/base_link.STL" />
      </geometry>
    </collision>
  </link>
  <link
    name="RF">
    <inertial>
      <origin
        xyz="0 5.20417042793042E-18 -0.00782717034564995"
        rpy="0 0 0" />
      <mass
        value="0.0489436503728706" />
      <inertia
        ixx="1.76621848414269E-05"
        ixy="-8.27180612553027E-22"
        ixz="-3.57780611824496E-22"
        iyy="1.76621848414269E-05"
        iyz="1.66224293062336E-22"
        izz="3.36011356425037E-05" />
    </inertial>
    <visual>
      <origin
        xyz="0 0 0"
        rpy="0 0 0" />
      <geometry>
        <mesh
          filename="package://urdf12/meshes/RF.STL" />
      </geometry>
      <material
        name="">
        <color
          rgba="0.792156862745098 0.819607843137255 0.933333333333333 1" />
      </material>
    </visual>
    <collision>
      <origin
        xyz="0 0 0"
        rpy="0 0 0" />
      <geometry>
        <mesh
          filename="package://urdf12/meshes/RF.STL" />
      </geometry>
    </collision>
  </link>
  <joint
    name="RFJ"
    type="continuous">
    <origin
      xyz="0.09 0.05 0.01"
      rpy="-1.5708 0 -1.5708" />
    <parent
      link="base_link" />
    <child
      link="RF" />
    <axis
      xyz="0 0 0" />
  </joint>
  <link
    name="RB">
    <inertial>
      <origin
        xyz="0 3.4694E-18 -0.0078272"
        rpy="0 0 0" />
      <mass
        value="0.048944" />
      <inertia
        ixx="1.7662E-05"
        ixy="-6.7208E-22"
        ixz="3.2739E-23"
        iyy="1.7662E-05"
        iyz="1.5206E-22"
        izz="3.3601E-05" />
    </inertial>
    <visual>
      <origin
        xyz="0 0 0"
        rpy="0 0 0" />
      <geometry>
        <mesh
          filename="package://urdf12/meshes/RB.STL" />
      </geometry>
      <material
        name="">
        <color
          rgba="0.79216 0.81961 0.93333 1" />
      </material>
    </visual>
    <collision>
      <origin
        xyz="0 0 0"
        rpy="0 0 0" />
      <geometry>
        <mesh
          filename="package://urdf12/meshes/RB.STL" />
      </geometry>
    </collision>
  </link>
  <joint
    name="RBJ"
    type="continuous">
    <origin
      xyz="0.09 -0.06 0.01"
      rpy="-1.5708 0 -1.5708" />
    <parent
      link="base_link" />
    <child
      link="RB" />
    <axis
      xyz="0 0 0" />
  </joint>
  <link
    name="LF">
    <inertial>
      <origin
        xyz="-6.9389E-18 -6.9389E-18 0.0078272"
        rpy="0 0 0" />
      <mass
        value="0.048944" />
      <inertia
        ixx="1.7662E-05"
        ixy="0"
        ixz="4.3937E-22"
        iyy="1.7662E-05"
        iyz="3.1634E-22"
        izz="3.3601E-05" />
    </inertial>
    <visual>
      <origin
        xyz="0 0 0"
        rpy="0 0 0" />
      <geometry>
        <mesh
          filename="package://urdf12/meshes/LF.STL" />
      </geometry>
      <material
        name="">
        <color
          rgba="0.79216 0.81961 0.93333 1" />
      </material>
    </visual>
    <collision>
      <origin
        xyz="0 0 0"
        rpy="0 0 0" />
      <geometry>
        <mesh
          filename="package://urdf12/meshes/LF.STL" />
      </geometry>
    </collision>
  </link>
  <joint
    name="LFJ"
    type="continuous">
    <origin
      xyz="-0.09 0.05 0.01"
      rpy="1.5708 0.91772 1.5708" />
    <parent
      link="base_link" />
    <child
      link="LF" />
    <axis
      xyz="0 0 0" />
  </joint>
  <link
    name="LB">
    <inertial>
      <origin
        xyz="0 0 0.0078272"
        rpy="0 0 0" />
      <mass
        value="0.048944" />
      <inertia
        ixx="1.7662E-05"
        ixy="1.6941E-21"
        ixz="6.9587E-22"
        iyy="1.7662E-05"
        iyz="-2.6788E-23"
        izz="3.3601E-05" />
    </inertial>
    <visual>
      <origin
        xyz="0 0 0"
        rpy="0 0 0" />
      <geometry>
        <mesh
          filename="package://urdf12/meshes/LB.STL" />
      </geometry>
      <material
        name="">
        <color
          rgba="0.79216 0.81961 0.93333 1" />
      </material>
    </visual>
    <collision>
      <origin
        xyz="0 0 0"
        rpy="0 0 0" />
      <geometry>
        <mesh
          filename="package://urdf12/meshes/LB.STL" />
      </geometry>
    </collision>
  </link>
  <joint
    name="LBJ"
    type="continuous">
    <origin
      xyz="-0.09 -0.06 0.01"
      rpy="1.5708 -0.58406 1.5708" />
    <parent
      link="base_link" />
    <child
      link="LB" />
    <axis
      xyz="0 0 0" />
  </joint>
</robot>