<?xml version="1.0" encoding="utf-8"?>
<!-- This URDF was automatically created by SolidWorks to URDF Exporter! Originally created by Stephen Brawner (brawner@gmail.com) 
     Commit Version: 1.6.0-1-g15f4949  Build Version: 1.6.7594.29634
     For more information, please see http://wiki.ros.org/sw_urdf_exporter -->
<robot
  name="robot_urdl">
  <link
    name="base_link">
    <inertial>
      <origin
        xyz="-4.30659230155655E-06 0.00991258876708149 -0.0221529540717541"
        rpy="0 0 0" />
      <mass
        value="0.734157679226463" />
      <inertia
        ixx="0.00351396795462361"
        ixy="2.71327909754855E-08"
        ixz="1.10768951074235E-07"
        iyy="0.00532306889577312"
        iyz="-4.71400775733585E-06"
        izz="0.00185783513184479" />
    </inertial>
    <visual>
      <origin
        xyz="0 0 0"
        rpy="0 0 0" />
      <geometry>
        <mesh
          filename="package://robot_urdl/meshes/base_link.STL" />
      </geometry>
      <material
        name="">
        <color
          rgba="0.792156862745098 0.819607843137255 0.933333333333333 1" />
      </material>
    </visual>
    <collision>
      <origin
        xyz="0 0 0"
        rpy="0 0 0" />
      <geometry>
        <mesh
          filename="package://robot_urdl/meshes/base_link.STL" />
      </geometry>
    </collision>
  </link>
  <link
    name="RB">
    <inertial>
      <origin
        xyz="-6.93889390390723E-18 3.46944695195361E-18 0.00717282965435007"
        rpy="0 0 0" />
      <mass
        value="0.0489436503728706" />
      <inertia
        ixx="1.7662184841427E-05"
        ixy="-8.75951149157412E-22"
        ixz="-4.78963396391322E-22"
        iyy="1.7662184841427E-05"
        iyz="9.87007059984379E-23"
        izz="3.36011356425037E-05" />
    </inertial>
    <visual>
      <origin
        xyz="0 0 0"
        rpy="0 0 0" />
      <geometry>
        <mesh
          filename="package://robot_urdl/meshes/RB.STL" />
      </geometry>
      <material
        name="">
        <color
          rgba="0.792156862745098 0.819607843137255 0.933333333333333 1" />
      </material>
    </visual>
    <collision>
      <origin
        xyz="0 0 0"
        rpy="0 0 0" />
      <geometry>
        <mesh
          filename="package://robot_urdl/meshes/RB.STL" />
      </geometry>
    </collision>
  </link>
  <joint
    name="RBJ"
    type="continuous">
    <origin
      xyz="0.075 -0.06 0.01"
      rpy="-1.5708 0 -1.5708" />
    <parent
      link="base_link" />
    <child
      link="RB" />
    <axis
      xyz="0 0 1" />
  </joint>
  <link
    name="RF">
    <inertial>
      <origin
        xyz="0 5.20417042793042E-18 0.00717282965435008"
        rpy="0 0 0" />
      <mass
        value="0.0489436503728706" />
      <inertia
        ixx="1.76621848414269E-05"
        ixy="-7.22268423045875E-22"
        ixz="-3.14715502260394E-22"
        iyy="1.76621848414269E-05"
        iyz="1.61890246581367E-22"
        izz="3.36011356425037E-05" />
    </inertial>
    <visual>
      <origin
        xyz="0 0 0"
        rpy="0 0 0" />
      <geometry>
        <mesh
          filename="package://robot_urdl/meshes/RF.STL" />
      </geometry>
      <material
        name="">
        <color
          rgba="0.792156862745098 0.819607843137255 0.933333333333333 1" />
      </material>
    </visual>
    <collision>
      <origin
        xyz="0 0 0"
        rpy="0 0 0" />
      <geometry>
        <mesh
          filename="package://robot_urdl/meshes/RF.STL" />
      </geometry>
    </collision>
  </link>
  <joint
    name="RFJ"
    type="continuous">
    <origin
      xyz="0.075 0.05 0.01"
      rpy="-1.5708 0 -1.5708" />
    <parent
      link="base_link" />
    <child
      link="RF" />
    <axis
      xyz="0 0 1" />
  </joint>
  <link
    name="LB">
    <inertial>
      <origin
        xyz="0 -6.93889390390723E-18 -0.00717282965435007"
        rpy="0 0 0" />
      <mass
        value="0.0489436503728706" />
      <inertia
        ixx="1.7662184841427E-05"
        ixy="1.6940658945086E-21"
        ixz="6.7156543956493E-22"
        iyy="1.76621848414269E-05"
        iyz="-2.26920606556456E-23"
        izz="3.36011356425037E-05" />
    </inertial>
    <visual>
      <origin
        xyz="0 0 0"
        rpy="0 0 0" />
      <geometry>
        <mesh
          filename="package://robot_urdl/meshes/LB.STL" />
      </geometry>
      <material
        name="">
        <color
          rgba="0.792156862745098 0.819607843137255 0.933333333333333 1" />
      </material>
    </visual>
    <collision>
      <origin
        xyz="0 0 0"
        rpy="0 0 0" />
      <geometry>
        <mesh
          filename="package://robot_urdl/meshes/LB.STL" />
      </geometry>
    </collision>
  </link>
  <joint
    name="LBJ"
    type="continuous">
    <origin
      xyz="-0.075 -0.06 0.01"
      rpy="1.5708 -0.58406 1.5708" />
    <parent
      link="base_link" />
    <child
      link="LB" />
    <axis
      xyz="0 0 1" />
  </joint>
  <link
    name="LF">
    <inertial>
      <origin
        xyz="-6.93889390390723E-18 -6.93889390390723E-18 -0.00717282965435005"
        rpy="0 0 0" />
      <mass
        value="0.0489436503728706" />
      <inertia
        ixx="1.76621848414269E-05"
        ixy="0"
        ixz="4.30423722666618E-22"
        iyy="1.76621848414269E-05"
        iyz="3.09057232406223E-22"
        izz="3.36011356425037E-05" />
    </inertial>
    <visual>
      <origin
        xyz="0 0 0"
        rpy="0 0 0" />
      <geometry>
        <mesh
          filename="package://robot_urdl/meshes/LF.STL" />
      </geometry>
      <material
        name="">
        <color
          rgba="0.792156862745098 0.819607843137255 0.933333333333333 1" />
      </material>
    </visual>
    <collision>
      <origin
        xyz="0 0 0"
        rpy="0 0 0" />
      <geometry>
        <mesh
          filename="package://robot_urdl/meshes/LF.STL" />
      </geometry>
    </collision>
  </link>
  <joint
    name="LFJ"
    type="continuous">
    <origin
      xyz="-0.075 0.05 0.01"
      rpy="1.5708 0.91772 1.5708" />
    <parent
      link="base_link" />
    <child
      link="LF" />
    <axis
      xyz="0 0 1" />
  </joint>
</robot>