<?xml version="1.0" encoding="utf-8"?>
<!-- This URDF was automatically created by SolidWorks to URDF Exporter! Originally created by Stephen Brawner (brawner@gmail.com) 
     Commit Version: 1.6.0-1-g15f4949  Build Version: 1.6.7594.29634
     For more information, please see http://wiki.ros.org/sw_urdf_exporter -->
<robot
  name="urdf8">
  <link
    name="base_link">
    <inertial>
      <origin
        xyz="-4.30659230155805E-06 0.00991258876708149 -0.0221529540717541"
        rpy="0 0 0" />
      <mass
        value="0.734157679226464" />
      <inertia
        ixx="0.00351396795462361"
        ixy="2.71327909754843E-08"
        ixz="1.10768951074236E-07"
        iyy="0.00532306889577312"
        iyz="-4.71400775733584E-06"
        izz="0.00185783513184479" />
    </inertial>
    <visual>
      <origin
        xyz="0 0 0"
        rpy="0 0 0" />
      <geometry>
        <mesh
          filename="package://urdf8/meshes/base_link.STL" />
      </geometry>
      <material
        name="">
        <color
          rgba="0.792156862745098 0.819607843137255 0.933333333333333 1" />
      </material>
    </visual>
    <collision>
      <origin
        xyz="0 0 0"
        rpy="0 0 0" />
      <geometry>
        <mesh
          filename="package://urdf8/meshes/base_link.STL" />
      </geometry>
    </collision>
  </link>
  <link
    name="RF">
    <inertial>
      <origin
        xyz="0 5.20417042793042E-18 0.00717282965435008"
        rpy="0 0 0" />
      <mass
        value="0.0489436503728706" />
      <inertia
        ixx="1.76621848414269E-05"
        ixy="-7.24460713560235E-22"
        ixz="-3.13306800713578E-22"
        iyy="1.76621848414269E-05"
        iyz="1.60846949927884E-22"
        izz="3.36011356425037E-05" />
    </inertial>
    <visual>
      <origin
        xyz="0 0 0"
        rpy="0 0 0" />
      <geometry>
        <mesh
          filename="package://urdf8/meshes/RF.STL" />
      </geometry>
      <material
        name="">
        <color
          rgba="0.792156862745098 0.819607843137255 0.933333333333333 1" />
      </material>
    </visual>
    <collision>
      <origin
        xyz="0 0 0"
        rpy="0 0 0" />
      <geometry>
        <mesh
          filename="package://urdf8/meshes/RF.STL" />
      </geometry>
    </collision>
  </link>
  <joint
    name="RFJ"
    type="continuous">
    <origin
      xyz="0.075 0.05 0.01"
      rpy="-1.5707963267949 0 -1.5707963267949" />
    <parent
      link="base_link" />
    <child
      link="RF" />
    <axis
      xyz="0 0 1" />
  </joint>
  <link
    name="RB">
    <inertial>
      <origin
        xyz="0 5.20417042793042E-18 0.00717282965435007"
        rpy="0 0 0" />
      <mass
        value="0.0489436503728706" />
      <inertia
        ixx="1.7662184841427E-05"
        ixy="-7.24490467748315E-22"
        ixz="8.38443426262884E-23"
        iyy="1.7662184841427E-05"
        iyz="1.70068575584028E-22"
        izz="3.36011356425037E-05" />
    </inertial>
    <visual>
      <origin
        xyz="0 0 0"
        rpy="0 0 0" />
      <geometry>
        <mesh
          filename="package://urdf8/meshes/RB.STL" />
      </geometry>
      <material
        name="">
        <color
          rgba="0.792156862745098 0.819607843137255 0.933333333333333 1" />
      </material>
    </visual>
    <collision>
      <origin
        xyz="0 0 0"
        rpy="0 0 0" />
      <geometry>
        <mesh
          filename="package://urdf8/meshes/RB.STL" />
      </geometry>
    </collision>
  </link>
  <joint
    name="RBJ"
    type="continuous">
    <origin
      xyz="0.0749999999999999 -0.06 0.01"
      rpy="-1.5707963267949 0 -1.5707963267949" />
    <parent
      link="base_link" />
    <child
      link="RB" />
    <axis
      xyz="0 0 1" />
  </joint>
  <link
    name="LF">
    <inertial>
      <origin
        xyz="-6.93889390390723E-18 -6.93889390390723E-18 -0.00717282965435005"
        rpy="0 0 0" />
      <mass
        value="0.0489436503728706" />
      <inertia
        ixx="1.76621848414269E-05"
        ixy="0"
        ixz="4.39518392954427E-22"
        iyy="1.76621848414269E-05"
        iyz="3.14797632781275E-22"
        izz="3.36011356425037E-05" />
    </inertial>
    <visual>
      <origin
        xyz="0 0 0"
        rpy="0 0 0" />
      <geometry>
        <mesh
          filename="package://urdf8/meshes/LF.STL" />
      </geometry>
      <material
        name="">
        <color
          rgba="0.792156862745098 0.819607843137255 0.933333333333333 1" />
      </material>
    </visual>
    <collision>
      <origin
        xyz="0 0 0"
        rpy="0 0 0" />
      <geometry>
        <mesh
          filename="package://urdf8/meshes/LF.STL" />
      </geometry>
    </collision>
  </link>
  <joint
    name="LFJ"
    type="continuous">
    <origin
      xyz="-0.075 0.05 0.01"
      rpy="1.5707963267949 0.917718602617513 1.5707963267949" />
    <parent
      link="base_link" />
    <child
      link="LF" />
    <axis
      xyz="0 0 1" />
  </joint>
  <link
    name="LB">
    <inertial>
      <origin
        xyz="0 -6.93889390390723E-18 -0.00717282965435007"
        rpy="0 0 0" />
      <mass
        value="0.0489436503728706" />
      <inertia
        ixx="1.7662184841427E-05"
        ixy="1.6940658945086E-21"
        ixz="6.93614655932614E-22"
        iyy="1.76621848414269E-05"
        iyz="-2.64546954309672E-23"
        izz="3.36011356425037E-05" />
    </inertial>
    <visual>
      <origin
        xyz="0 0 0"
        rpy="0 0 0" />
      <geometry>
        <mesh
          filename="package://urdf8/meshes/LB.STL" />
      </geometry>
      <material
        name="">
        <color
          rgba="0.792156862745098 0.819607843137255 0.933333333333333 1" />
      </material>
    </visual>
    <collision>
      <origin
        xyz="0 0 0"
        rpy="0 0 0" />
      <geometry>
        <mesh
          filename="package://urdf8/meshes/LB.STL" />
      </geometry>
    </collision>
  </link>
  <joint
    name="LBJ"
    type="continuous">
    <origin
      xyz="-0.075 -0.06 0.01"
      rpy="1.5707963267949 -0.584056750958047 1.5707963267949" />
    <parent
      link="base_link" />
    <child
      link="LB" />
    <axis
      xyz="0 0 1" />
  </joint>
</robot>