<?xml version="1.0" encoding="utf-8"?>
<!-- This URDF was automatically created by SolidWorks to URDF Exporter! Originally created by Stephen Brawner (brawner@gmail.com) 
     Commit Version: 1.6.0-1-g15f4949  Build Version: 1.6.7594.29634
     For more information, please see http://wiki.ros.org/sw_urdf_exporter -->
<robot
  name="urdf5">
  <link
    name="base_link">
    <inertial>
      <origin
        xyz="-4.3065923015566E-06 0.0221529540717541 0.00991258876708148"
        rpy="0 0 0" />
      <mass
        value="0.734157679226463" />
      <inertia
        ixx="0.00351396795462361"
        ixy="-1.10768951074185E-07"
        ixz="2.71327909754854E-08"
        iyy="0.00185783513184479"
        iyz="4.71400775733606E-06"
        izz="0.00532306889577312" />
    </inertial>
    <visual>
      <origin
        xyz="0 0 0"
        rpy="0 0 0" />
      <geometry>
        <mesh
          filename="package://urdf5/meshes/base_link.STL" />
      </geometry>
      <material
        name="">
        <color
          rgba="0.792156862745098 0.819607843137255 0.933333333333333 1" />
      </material>
    </visual>
    <collision>
      <origin
        xyz="0 0 0"
        rpy="0 0 0" />
      <geometry>
        <mesh
          filename="package://urdf5/meshes/base_link.STL" />
      </geometry>
    </collision>
  </link>
  <link
    name="RF">
    <inertial>
      <origin
        xyz="6.93889390390723E-18 3.46944695195361E-18 0.00717282965435007"
        rpy="0 0 0" />
      <mass
        value="0.0489436503728706" />
      <inertia
        ixx="1.76621848414269E-05"
        ixy="-7.23783035983899E-22"
        ixz="-3.11701655694594E-22"
        iyy="1.76621848414269E-05"
        iyz="1.62936887161284E-22"
        izz="3.36011356425037E-05" />
    </inertial>
    <visual>
      <origin
        xyz="0 0 0"
        rpy="0 0 0" />
      <geometry>
        <mesh
          filename="package://urdf5/meshes/RF.STL" />
      </geometry>
      <material
        name="">
        <color
          rgba="0.792156862745098 0.819607843137255 0.933333333333333 1" />
      </material>
    </visual>
    <collision>
      <origin
        xyz="0 0 0"
        rpy="0 0 0" />
      <geometry>
        <mesh
          filename="package://urdf5/meshes/RF.STL" />
      </geometry>
    </collision>
  </link>
  <joint
    name="RFJ"
    type="continuous">
    <origin
      xyz="0.075 0.05 0.01"
      rpy="-1.5707963267949 0 -1.5707963267949" />
    <parent
      link="base_link" />
    <child
      link="RF" />
    <axis
      xyz="0 0 1" />
  </joint>
  <link
    name="RB">
    <inertial>
      <origin
        xyz="-6.93889390390723E-18 6.93889390390723E-18 0.00717282965435007"
        rpy="0 0 0" />
      <mass
        value="0.0489436503728706" />
      <inertia
        ixx="1.7662184841427E-05"
        ixy="-8.65954703766451E-22"
        ixz="-4.6479789450203E-22"
        iyy="1.7662184841427E-05"
        iyz="9.65745457224752E-23"
        izz="3.36011356425037E-05" />
    </inertial>
    <visual>
      <origin
        xyz="0 0 0"
        rpy="0 0 0" />
      <geometry>
        <mesh
          filename="package://urdf5/meshes/RB.STL" />
      </geometry>
      <material
        name="">
        <color
          rgba="0.792156862745098 0.819607843137255 0.933333333333333 1" />
      </material>
    </visual>
    <collision>
      <origin
        xyz="0 0 0"
        rpy="0 0 0" />
      <geometry>
        <mesh
          filename="package://urdf5/meshes/RB.STL" />
      </geometry>
    </collision>
  </link>
  <joint
    name="RBJ"
    type="continuous">
    <origin
      xyz="0.075 -0.06 0.01"
      rpy="-1.5707963267949 0 -1.5707963267949" />
    <parent
      link="base_link" />
    <child
      link="RB" />
    <axis
      xyz="0 0 1" />
  </joint>
  <link
    name="LF">
    <inertial>
      <origin
        xyz="-6.93889390390723E-18 -6.93889390390723E-18 -0.00717282965435005"
        rpy="0 0 0" />
      <mass
        value="0.0489436503728706" />
      <inertia
        ixx="1.76621848414269E-05"
        ixy="1.6940658945086E-21"
        ixz="4.39284338123991E-22"
        iyy="1.76621848414269E-05"
        iyz="3.1501386768452E-22"
        izz="3.36011356425037E-05" />
    </inertial>
    <visual>
      <origin
        xyz="0 0 0"
        rpy="0 0 0" />
      <geometry>
        <mesh
          filename="package://urdf5/meshes/LF.STL" />
      </geometry>
      <material
        name="">
        <color
          rgba="0.792156862745098 0.819607843137255 0.933333333333333 1" />
      </material>
    </visual>
    <collision>
      <origin
        xyz="0 0 0"
        rpy="0 0 0" />
      <geometry>
        <mesh
          filename="package://urdf5/meshes/LF.STL" />
      </geometry>
    </collision>
  </link>
  <joint
    name="LFJ"
    type="continuous">
    <origin
      xyz="-0.075 0.05 0.01"
      rpy="1.5707963267949 0.917718602617513 1.5707963267949" />
    <parent
      link="base_link" />
    <child
      link="LF" />
    <axis
      xyz="0 0 1" />
  </joint>
  <link
    name="LR">
    <inertial>
      <origin
        xyz="0 0 -0.00717282965435008"
        rpy="0 0 0" />
      <mass
        value="0.0489436503728706" />
      <inertia
        ixx="1.76621848414269E-05"
        ixy="3.3881317890172E-21"
        ixz="6.92279468509898E-22"
        iyy="1.76621848414269E-05"
        iyz="-2.44335334380697E-23"
        izz="3.36011356425037E-05" />
    </inertial>
    <visual>
      <origin
        xyz="0 0 0"
        rpy="0 0 0" />
      <geometry>
        <mesh
          filename="package://urdf5/meshes/LR.STL" />
      </geometry>
      <material
        name="">
        <color
          rgba="0.792156862745098 0.819607843137255 0.933333333333333 1" />
      </material>
    </visual>
    <collision>
      <origin
        xyz="0 0 0"
        rpy="0 0 0" />
      <geometry>
        <mesh
          filename="package://urdf5/meshes/LR.STL" />
      </geometry>
    </collision>
  </link>
  <joint
    name="LRJ"
    type="continuous">
    <origin
      xyz="-0.075 -0.06 0.01"
      rpy="1.5707963267949 -0.584056750958047 1.5707963267949" />
    <parent
      link="base_link" />
    <child
      link="LR" />
    <axis
      xyz="0 0 1" />
  </joint>
</robot>