<?xml version="1.0" encoding="utf-8"?>
<!-- This URDF was automatically created by SolidWorks to URDF Exporter! Originally created by Stephen Brawner (brawner@gmail.com) 
     Commit Version: 1.6.0-1-g15f4949  Build Version: 1.6.7594.29634
     For more information, please see http://wiki.ros.org/sw_urdf_exporter -->
<robot
  name="urdf10">
  <link
    name="base_link">
    <inertial>
      <origin
        xyz="-1.238E-17 0.009928 -0.022088"
        rpy="0 0 0" />
      <mass
        value="0.73548" />
      <inertia
        ixx="0.0035158"
        ixy="1.4597E-21"
        ixz="-1.0428E-18"
        iyy="0.0053257"
        iyz="-5.1248E-06"
        izz="0.0018588" />
    </inertial>
    <visual>
      <origin
        xyz="0 0 0"
        rpy="0 0 0" />
      <geometry>
        <mesh
          filename="package://urdf10/meshes/base_link.STL" />
      </geometry>
      <material
        name="">
        <color
          rgba="0.79216 0.81961 0.93333 1" />
      </material>
    </visual>
    <collision>
      <origin
        xyz="0 0 0"
        rpy="0 0 0" />
      <geometry>
        <mesh
          filename="package://urdf10/meshes/base_link.STL" />
      </geometry>
    </collision>
  </link>
  <link
    name="RF">
    <inertial>
      <origin
        xyz="0 5.20417042793042E-18 -0.00782717034564995"
        rpy="0 0 0" />
      <mass
        value="0.0489436503728706" />
      <inertia
        ixx="1.76621848414269E-05"
        ixy="-8.19506573667038E-22"
        ixz="-3.55066315822392E-22"
        iyy="1.76621848414269E-05"
        iyz="1.68025079304297E-22"
        izz="3.36011356425037E-05" />
    </inertial>
    <visual>
      <origin
        xyz="0 0 0"
        rpy="0 0 0" />
      <geometry>
        <mesh
          filename="package://urdf10/meshes/RF.STL" />
      </geometry>
      <material
        name="">
        <color
          rgba="0.792156862745098 0.819607843137255 0.933333333333333 1" />
      </material>
    </visual>
    <collision>
      <origin
        xyz="0 0 0"
        rpy="0 0 0" />
      <geometry>
        <mesh
          filename="package://urdf10/meshes/RF.STL" />
      </geometry>
    </collision>
  </link>
  <joint
    name="RFJ"
    type="continuous">
    <origin
      xyz="0.09 0.05 0.01"
      rpy="-1.5708 0 -1.5708" />
    <parent
      link="base_link" />
    <child
      link="RF" />
    <axis
      xyz="0 0 0" />
  </joint>
  <link
    name="RB">
    <inertial>
      <origin
        xyz="0 3.46944695195361E-18 -0.00782717034564995"
        rpy="0 0 0" />
      <mass
        value="0.0489436503728706" />
      <inertia
        ixx="1.7662184841427E-05"
        ixy="-6.7375032193116E-22"
        ixz="3.25438614416667E-23"
        iyy="1.7662184841427E-05"
        iyz="1.52977332062342E-22"
        izz="3.36011356425037E-05" />
    </inertial>
    <visual>
      <origin
        xyz="0 0 0"
        rpy="0 0 0" />
      <geometry>
        <mesh
          filename="package://urdf10/meshes/RB.STL" />
      </geometry>
      <material
        name="">
        <color
          rgba="0.792156862745098 0.819607843137255 0.933333333333333 1" />
      </material>
    </visual>
    <collision>
      <origin
        xyz="0 0 0"
        rpy="0 0 0" />
      <geometry>
        <mesh
          filename="package://urdf10/meshes/RB.STL" />
      </geometry>
    </collision>
  </link>
  <joint
    name="RBJ"
    type="continuous">
    <origin
      xyz="0.09 -0.06 0.01"
      rpy="-1.5708 0 -1.5708" />
    <parent
      link="base_link" />
    <child
      link="RB" />
    <axis
      xyz="0 0 0" />
  </joint>
  <link
    name="LF">
    <inertial>
      <origin
        xyz="-6.93889390390723E-18 -6.93889390390723E-18 0.00782717034564995"
        rpy="0 0 0" />
      <mass
        value="0.0489436503728706" />
      <inertia
        ixx="1.76621848414269E-05"
        ixy="-8.470329472543E-22"
        ixz="4.40041994907905E-22"
        iyy="1.76621848414269E-05"
        iyz="3.14249351544543E-22"
        izz="3.36011356425037E-05" />
    </inertial>
    <visual>
      <origin
        xyz="0 0 0"
        rpy="0 0 0" />
      <geometry>
        <mesh
          filename="package://urdf10/meshes/LF.STL" />
      </geometry>
      <material
        name="">
        <color
          rgba="0.792156862745098 0.819607843137255 0.933333333333333 1" />
      </material>
    </visual>
    <collision>
      <origin
        xyz="0 0 0"
        rpy="0 0 0" />
      <geometry>
        <mesh
          filename="package://urdf10/meshes/LF.STL" />
      </geometry>
    </collision>
  </link>
  <joint
    name="LFJ"
    type="continuous">
    <origin
      xyz="-0.09 0.05 0.01"
      rpy="1.5708 0.91772 1.5708" />
    <parent
      link="base_link" />
    <child
      link="LF" />
    <axis
      xyz="0 0 0" />
  </joint>
  <link
    name="LB">
    <inertial>
      <origin
        xyz="0 0 0"
        rpy="0 0 0" />
      <mass
        value="0" />
      <inertia
        ixx="0"
        ixy="0"
        ixz="0"
        iyy="0"
        iyz="0"
        izz="0" />
    </inertial>
    <visual>
      <origin
        xyz="0 0 0"
        rpy="0 0 0" />
      <geometry>
        <mesh
          filename="package://urdf10/meshes/LB.STL" />
      </geometry>
      <material
        name="">
        <color
          rgba="1 1 1 1" />
      </material>
    </visual>
    <collision>
      <origin
        xyz="0 0 0"
        rpy="0 0 0" />
      <geometry>
        <mesh
          filename="package://urdf10/meshes/LB.STL" />
      </geometry>
    </collision>
  </link>
  <joint
    name="LBJ"
    type="continuous">
    <origin
      xyz="-0.09 -0.06 0.01"
      rpy="1.5708 -0.58406 1.5708" />
    <parent
      link="base_link" />
    <child
      link="LB" />
    <axis
      xyz="0 0 0" />
  </joint>
</robot>