<?xml version="1.0" encoding="utf-8"?>
<!-- This URDF was automatically created by SolidWorks to URDF Exporter! Originally created by Stephen Brawner (brawner@gmail.com) 
     Commit Version: 1.6.0-1-g15f4949  Build Version: 1.6.7594.29634
     For more information, please see http://wiki.ros.org/sw_urdf_exporter -->
<robot
  name="floorassemblr1049">
  <link
    name="base_link">
    <inertial>
      <origin
        xyz="0.148588308492964 -1.66609995121903 0.932077952055182"
        rpy="0 0 0" />
      <mass
        value="5" />
      <inertia
        ixx="0.416708333333334"
        ixy="-1.15648231731787E-18"
        ixz="7.08117796935346E-35"
        iyy="0.104208333333333"
        iyz="2.55100811080624E-17"
        izz="0.520833333333334" />
    </inertial>
    <visual>
      <origin
        xyz="0 0 0"
        rpy="0 0 0" />
      <geometry>
        <mesh
          filename="package://floorassemblr1049/meshes/base_link.STL" />
      </geometry>
      <material
        name="">
        <color
          rgba="0.796078431372549 0.823529411764706 0.937254901960784 1" />
      </material>
    </visual>
    <collision>
      <origin
        xyz="0 0 0"
        rpy="0 0 0" />
      <geometry>
        <mesh
          filename="package://floorassemblr1049/meshes/base_link.STL" />
      </geometry>
    </collision>
  </link>
  <link
    name="dfsdf">
    <inertial>
      <origin
        xyz="0 0.00500000000000012 2.22044604925031E-16"
        rpy="0 0 0" />
      <mass
        value="5" />
      <inertia
        ixx="0.416708333333334"
        ixy="0"
        ixz="0"
        iyy="0.520833333333334"
        iyz="-1.72755351774246E-35"
        izz="0.104208333333333" />
    </inertial>
    <visual>
      <origin
        xyz="0 0 0"
        rpy="0 0 0" />
      <geometry>
        <mesh
          filename="package://floorassemblr1049/meshes/dfsdf.STL" />
      </geometry>
      <material
        name="">
        <color
          rgba="0.796078431372549 0.823529411764706 0.937254901960784 1" />
      </material>
    </visual>
    <collision>
      <origin
        xyz="0 0 0"
        rpy="0 0 0" />
      <geometry>
        <mesh
          filename="package://floorassemblr1049/meshes/dfsdf.STL" />
      </geometry>
    </collision>
  </link>
  <joint
    name="ser"
    type="floating">
    <origin
      xyz="0.64859 -1.6661 0.92708"
      rpy="1.5708 0 0" />
    <parent
      link="base_link" />
    <child
      link="dfsdf" />
    <axis
      xyz="0 0 0" />
  </joint>
</robot>