<?xml version="1.0" encoding="utf-8"?>
<!-- This URDF was automatically created by SolidWorks to URDF Exporter! Originally created by Stephen Brawner (brawner@gmail.com) 
     Commit Version: 1.6.0-1-g15f4949  Build Version: 1.6.7594.29634
     For more information, please see http://wiki.ros.org/sw_urdf_exporter -->
<robot
  name="Assem1">
  <link
    name="base_link">
    <inertial>
      <origin
        xyz="-4.3066E-06 0.0099126 -0.022153"
        rpy="0 0 0" />
      <mass
        value="0.73416" />
      <inertia
        ixx="0.003514"
        ixy="2.7133E-08"
        ixz="1.1077E-07"
        iyy="0.0053231"
        iyz="-4.714E-06"
        izz="0.0018578" />
    </inertial>
    <visual>
      <origin
        xyz="0 0 0"
        rpy="0 0 0" />
      <geometry>
        <mesh
          filename="package://Assem1/meshes/base_link.STL" />
      </geometry>
      <material
        name="">
        <color
          rgba="1 0 0 1" />
      </material>
    </visual>
    <collision>
      <origin
        xyz="0 0 0"
        rpy="0 0 0" />
      <geometry>
        <mesh
          filename="package://Assem1/meshes/base_link.STL" />
      </geometry>
    </collision>
  </link>
  <link
    name="RF">
    <inertial>
      <origin
        xyz="0 5.2042E-18 0.0071728"
        rpy="0 0 0" />
      <mass
        value="0.048944" />
      <inertia
        ixx="1.7662E-05"
        ixy="-7.1119E-22"
        ixz="-3.1126E-22"
        iyy="1.7662E-05"
        iyz="1.6055E-22"
        izz="3.3601E-05" />
    </inertial>
    <visual>
      <origin
        xyz="0 0 0"
        rpy="0 0 0" />
      <geometry>
        <mesh
          filename="package://Assem1/meshes/RF.STL" />
      </geometry>
      <material
        name="">
        <color
          rgba="0.79216 0.81961 0.93333 1" />
      </material>
    </visual>
    <collision>
      <origin
        xyz="0 0 0"
        rpy="0 0 0" />
      <geometry>
        <mesh
          filename="package://Assem1/meshes/RF.STL" />
      </geometry>
    </collision>
  </link>
  <joint
    name="RFJ"
    type="continuous">
    <origin
      xyz="0.075 0.05 0.01"
      rpy="-1.5708 0 -1.5708" />
    <parent
      link="base_link" />
    <child
      link="RF" />
    <axis
      xyz="0 0 1" />
  </joint>
  <link
    name="RB">
    <inertial>
      <origin
        xyz="-6.9389E-18 3.4694E-18 0.0071728"
        rpy="0 0 0" />
      <mass
        value="0.048944" />
      <inertia
        ixx="1.7662E-05"
        ixy="-8.7888E-22"
        ixz="-4.6048E-22"
        iyy="1.7662E-05"
        iyz="9.8194E-23"
        izz="3.3601E-05" />
    </inertial>
    <visual>
      <origin
        xyz="0 0 0"
        rpy="0 0 0" />
      <geometry>
        <mesh
          filename="package://Assem1/meshes/RB.STL" />
      </geometry>
      <material
        name="">
        <color
          rgba="0.79216 0.81961 0.93333 1" />
      </material>
    </visual>
    <collision>
      <origin
        xyz="0 0 0"
        rpy="0 0 0" />
      <geometry>
        <mesh
          filename="package://Assem1/meshes/RB.STL" />
      </geometry>
    </collision>
  </link>
  <joint
    name="RBJ"
    type="continuous">
    <origin
      xyz="0.075 -0.06 0.01"
      rpy="-1.5708 0 -1.5708" />
    <parent
      link="base_link" />
    <child
      link="RB" />
    <axis
      xyz="0 0 1" />
  </joint>
  <link
    name="LF">
    <inertial>
      <origin
        xyz="-3.4694E-18 -6.9389E-18 -0.0071728"
        rpy="0 0 0" />
      <mass
        value="0.048944" />
      <inertia
        ixx="1.7662E-05"
        ixy="0"
        ixz="4.4071E-22"
        iyy="1.7662E-05"
        iyz="3.1556E-22"
        izz="3.3601E-05" />
    </inertial>
    <visual>
      <origin
        xyz="0 0 0"
        rpy="0 0 0" />
      <geometry>
        <mesh
          filename="package://Assem1/meshes/LF.STL" />
      </geometry>
      <material
        name="">
        <color
          rgba="0.79216 0.81961 0.93333 1" />
      </material>
    </visual>
    <collision>
      <origin
        xyz="0 0 0"
        rpy="0 0 0" />
      <geometry>
        <mesh
          filename="package://Assem1/meshes/LF.STL" />
      </geometry>
    </collision>
  </link>
  <joint
    name="LFJ"
    type="continuous">
    <origin
      xyz="-0.075 0.05 0.01"
      rpy="1.5707963267949 0.917718602617513 1.5707963267949" />
    <parent
      link="base_link" />
    <child
      link="LF" />
    <axis
      xyz="0 0 1" />
  </joint>
  <link
    name="LB">
    <inertial>
      <origin
        xyz="0 -6.9389E-18 -0.0071728"
        rpy="0 0 0" />
      <mass
        value="0.048944" />
      <inertia
        ixx="1.7662E-05"
        ixy="2.5411E-21"
        ixz="6.9193E-22"
        iyy="1.7662E-05"
        iyz="-2.3943E-23"
        izz="3.3601E-05" />
    </inertial>
    <visual>
      <origin
        xyz="0 0 0"
        rpy="0 0 0" />
      <geometry>
        <mesh
          filename="package://Assem1/meshes/LB.STL" />
      </geometry>
      <material
        name="">
        <color
          rgba="0.79216 0.81961 0.93333 1" />
      </material>
    </visual>
    <collision>
      <origin
        xyz="0 0 0"
        rpy="0 0 0" />
      <geometry>
        <mesh
          filename="package://Assem1/meshes/LB.STL" />
      </geometry>
    </collision>
  </link>
  <joint
    name="LBJ"
    type="continuous">
    <origin
      xyz="-0.075 -0.06 0.01"
      rpy="1.5708 -0.58406 1.5708" />
    <parent
      link="base_link" />
    <child
      link="LB" />
    <axis
      xyz="0 0 1" />
  </joint>
</robot>